Workbook
Name Category: Table1[Category]
Name Slicer_Category: #N/A
Name Slicer_Country: #N/A
Name Slicer_Product: #N/A

Sheet BLOSSOM ACADEMY

Sheet Data
A1: Order ID | B1: Product | C1: Category | D1: Amount | E1: Date | F1: Country
A2: 1 | B2: Carrots | C2: Vegetables | D2: 4270 | E2: 42375 | F2: United States
A3: 2 | B3: Cabbage | C3: Vegetables | D3: 8239 | E3: 42376 | F3: United Kingdom
A4: 3 | B4: Banana | C4: Fruit | D4: 617 | E4: 42377 | F4: United States
A5: 4 | B5: Banana | C5: Fruit | D5: 8384 | E5: 42379 | F5: Canada
A6: 5 | B6: Beans | C6: Vegetables | D6: 2626 | E6: 42379 | F6: Germany
A7: 6 | B7: Orange | C7: Fruit | D7: 3610 | E7: 42380 | F7: United States
A8: 7 | B8: Cabbage | C8: Vegetables | D8: 9062 | E8: 42380 | F8: Australia
A9: 8 | B9: Banana | C9: Fruit | D9: 6906 | E9: 42385 | F9: New Zealand
A10: 9 | B10: Apple | C10: Fruit | D10: 2417 | E10: 42385 | F10: France
A11: 10 | B11: Apple | C11: Fruit | D11: 7431 | E11: 42385 | F11: Canada
A12: 11 | B12: Banana | C12: Fruit | D12: 8250 | E12: 42385 | F12: Germany
A13: 12 | B13: Cabbage | C13: Vegetables | D13: 7012 | E13: 42387 | F13: United States
... A214: 213 | B214: Carrots | C214: Vegetables | D214: 339 | E214: 42734 | F214: Australia

Sheet Table
A1: Order ID | B1: Product | C1: Category | D1: Amount | E1: Date | F1: Country
A2: 1 | B2: Carrots | C2: Vegetables | D2: 4270 | E2: 42375 | F2: United States | H2: PRODUCT | K2: AMOUNT | T2: {=_xlfn.UNIQUE(Table1[Category])} -> Vegetables | V2: {=_xlfn.UNIQUE(Table1[Product])} -> Carrots | X2: {=_xlfn.UNIQUE(Category)} -> Vegetables | Z2: {=_xlfn.UNIQUE(Table1[Country])} -> United States
A3: 2 | B3: Cabbage | C3: Vegetables | D3: 8239 | E3: 42376 | F3: United Kingdom | H3: LEGEND | K3: LEGEND | T3: Fruit | V3: Cabbage | X3: Fruit | Z3: United Kingdom
A4: 3 | B4: Banana | C4: Fruit | D4: 617 | E4: 42377 | F4: United States | I4: Carrot | L4: Above average | V4: Banana | Z4: Canada
A5: 4 | B5: Banana | C5: Fruit | D5: 8384 | E5: 42379 | F5: Canada | I5: Cabbage | L5: Average | V5: Beans | Z5: Germany
A6: 5 | B6: Beans | C6: Vegetables | D6: 2626 | E6: 42379 | F6: Germany | I6: Banana | L6: Below avergae | V6: Orange | X6: =COUNTA(_xlfn.UNIQUE(Table1[Product])) -> 7 | Z6: Australia
A7: 6 | B7: Orange | C7: Fruit | D7: 3610 | E7: 42380 | F7: United States | I7: Beans | L7: Highest sales value | V7: Apple | Z7: New Zealand
A8: 7 | B8: Cabbage | C8: Vegetables | D8: 9062 | E8: 42380 | F8: Australia | I8: Orange | L8: Lowest sales value | V8: Mango | Z8: France
A9: 8 | B9: Banana | C9: Fruit | D9: 6906 | E9: 42385 | F9: New Zealand | I9: Apple
A10: 9 | B10: Apple | C10: Fruit | D10: 2417 | E10: 42385 | F10: France | I10: Mango
A11: 10 | B11: Apple | C11: Fruit | D11: 7431 | E11: 42385 | F11: Canada
A12: 11 | B12: Banana | C12: Fruit | D12: 8250 | E12: 42385 | F12: Germany
A13: 12 | B13: Cabbage | C13: Vegetables | D13: 7012 | E13: 42387 | F13: United States
A14: 13 | B14: Carrots | C14: Vegetables | D14: 1903 | E14: 42389 | F14: Germany
A15: 14 | B15: Cabbage | C15: Vegetables | D15: 2824 | E15: 42391 | F15: Canada
A16: 15 | B16: Apple | C16: Fruit | D16: 6946 | E16: 42393 | F16: France
A17: 16 | B17: Banana | C17: Fruit | D17: 2320 | E17: 42396 | F17: United Kingdom
A18: 17 | B18: Banana | C18: Fruit | D18: 2116 | E18: 42397 | F18: United States
A19: 18 | B19: Banana | C19: Fruit | D19: 1135 | E19: 42399 | F19: United Kingdom
A20: 19 | B20: Cabbage | C20: Vegetables | D20: 3595 | E20: 42399 | F20: United Kingdom
A21: 20 | B21: Apple | C21: Fruit | D21: 1161 | E21: 42402 | F21: United States
A22: 21 | B22: Orange | C22: Fruit | D22: 2256 | E22: 42404 | F22: France
... A214: 213 | B214: Carrots | C214: Vegetables | D214: 339 | E214: 42734 | F214: Australia

Sheet Descriptions
A1: WHAT I AM LOOKING FOR | B1: RETURNED VALUE | D1: EXPLANATION
A2: TOTAL SALES FOR VEGETABLES | B2: =SUM(Table1[Amount]) -> 1029734 | D2: Use sum function to find the total sales for vegetables
A3: TOTAL SALES FOR FRUITS | B3: =SUM(Table!D4:D212) -> 1014273 | D3: Use sum function to find the total sales for vegetables
A4: AVERAGE SALES FOR VEGETABLES | B4: =AVERAGE(Table1[Amount]) -> 4834.4319 | D4: Average Sales of Vegetables
A5: AVERAGE SALES FOR FRUITS | B5: =AVERAGE(Table!D4:D212) -> 4852.9809 | D5: Average sales of fruits
A6: COUNT OF VEGETABLES | B6: =COUNTIF(Table1[Category],Table!T2) -> 67 | D6: Used countif to find the total count of vegetables in the dataset
A7: COUNT OF FRUITS | B7: =COUNTIF(Table1[Category],Table!T3) -> 146 | D7: Used countif to find the total count of fruits in the dataset
A8: COUNT OF CARROTS | B8: =COUNTIF(Table1[Product],Table!V2) -> 27 | D8: Used countif to find the total count of carrot in the dataset
A9: COUNT OF CABBAGE | B9: =COUNTIF(Table1[Product],Table!V3) -> 27 | D9: Used countif to find the total count of cabbage in the dataset
A10: COUNT OF BANANA | B10: =COUNTIF(Table1[Product],Table!V4) -> 71 | D10: Used countif to find the total count of banana in the dataset
A11: COUNT OF BEANS | B11: =COUNTIF(Table1[Product],Table!V5) -> 13 | D11: Used countif to find the total count of beans in the dataset
A12: COUNT OF ORANGE | B12: =COUNTIF(Table1[Product],Table!V6) -> 24 | D12: Used countif to find the total count of oranges in the dataset
A13: COUNT OF APPLE | B13: =COUNTIF(Table1[Product],Table!V7) -> 40 | D13: Used countif to find the total count of apples in the dataset
A14: COUNT OF MANGO | B14: =COUNTIF(Table1[Product],Table!V8) -> 11 | D14: Used countif to find the total count of mangoes in the dataset
A15: LOWEST SALES VALUE | B15: =MIN(Table1[Amount]) -> 107 | D15: Used min function to find the lowest sales value
A16: HIGHEST SALES VALUE | B16: =MAX(Table1[Amount]) -> 9990 | D16: Used max function to find the highest
A17: HIGHEST SALES VALUE | B17: 9990 | D17: Used conditional formatting to find the highest sales and highlighted it in green
A18: LOWEST SALES VALUE | B18: 107 | D18: Used conditional formatting to find the lowest sales and highlighted it in red
A19: RANGE OF SALES VALUE | B19: refer to Table | D19: Used conditional formatting (Icon set) to find the range pf sales value. Values that are greater than or equal to 67% were highlighted in green, those that were less than or equal to 67% highlighted in yello and those that were less than or equal to 33% highlighted in red.
A20: CELLS CONTAINING PARTICULAR WORDS | B20: refer to Table | D20: Used contional formating to identify cells containing particular words(carrot -highlighted in red, cabbage highlighted in purple, banana highlighted in yello, orange highlighted in orange and beans highlighted in beans)
A21: NUMBER OF SALES IN UNITED SATES | B21: =COUNTIF(Table1[Country],"United States") -> 57 | D21: Used countif to find the number of sales in the united states
A22: NUMBER OF CARROTS SOLD IN THE UNITED KINGDOM | B22: =COUNTIFS(Table1[Country],Table!Z3,Table1[Category],Table!T2,Table1[Product],Table!V2) -> 7 | D22: Used countifs to determine the number of carrots sold in the united kingdom
A23: DATE FOR ORDER 1D 25 | B23: =VLOOKUP(Table!A26,Table1[],5,FALSE) -> 42417 | D23: Used Vlookup to find the order date for ID 25
A24: AMOUNT APPLE WAS SOLD FOR ORDER ID 10 | B24: =VLOOKUP(Table!A11,Table1[],4,FALSE) -> 7431 | D24: Used vlookup to identify how much order ID 10 bought their apple
A25: COUNTRY WHERE ORANGE WAS SOLD(first instance in the table) | B25: =VLOOKUP("Orange",Table1[[Product]:[Country]],5,FALSE) -> United States | D25: Used vlookup to identify the first instance in the table where orange was sold and in what country
A26: CATEGORY OF BANANA | B26: =VLOOKUP("Banana",Table1[[Product]:[Country]],2,FALSE) -> Fruit | D26: Used Vlookup to find the category of banana from the dataset
A27: IF | B27: =IF(Table!B2="Carrots",Table!D2,0) -> 4270 | D27: Used if function to check for if cell b2 contains carrots and returns the corresponding amount
A28: MEDIAN SALES VALUE | B28: =MEDIAN(Table1[Amount]) -> 4781 | D28: Used Median to find the most middle number
A29: TOTAL AMOUNT OF ORANGES SOLD IN THE UNITED STATES | B29: =SUMIFS(Table1[Amount],Table1[Product],"Orange",Table1[Country],"United States") -> 30932 | D29: Used SUMIFSto find the amounts in column D where the product is “Orange” and the country is “United States”.
A30: NUMBER OF TIMES BEANS WERE SOLD IN THE UNITED KINGDOM | B30: =COUNTIFS(Table1[Product],"Beans",Table1[Country],"United Kingdom") -> 2 | D30: Used countifs to count the number of rows where the product is “Beans” and the country is “United Kingdom”.
A31: EXTRACTING FIRST 3 LETTERS | B31: =LEFT(Table!B2,3) -> Car | D31: Used the left function to extract the first 3 letters of carrots from cell b2
A32: CONVERTING TEXT TO CAPITAL LETTERS | B32: =UPPER(Table!C2) -> VEGETABLES | D32: Used Upper function to convert the text "Vegetable" in cell c2 into capital letters
A33: EXTRACTING LETTERS LAST 4 LETTERS OF A TEXT | B33: =RIGHT(Table!F6,4) -> many | D33: Used right function to extract the last 4 letters of "Germany" from cell F6
A34: EXTRACTING MID TEXT | B34: =MID(Table!B22,2,3) -> ran | D34: Used Mid function to extract 3 letters from orange in cell b22 starting from the 2 letter
A35: NUMBER OF CHARACTERS IN CELL F9 | B35: =LEN(Table!F9) -> 11 | D35: Used the LEN function to find the number of characters in "new zealand" cell F9
A36: UNIQUE CHARACTERS IN CATEGORY FIELD | B36: {=_xlfn.UNIQUE(Table1[Category])} -> Vegetables | D36: Useed Uique to identify the unique characters in category
B37: Fruit
A38: MOST FREQUENTLY OCCURING SALES VALUE | B38: =MODE(Table1[Date]) -> 42385 | D38: Used mode to calculate the most frequent occuring sales value
A39: STANDARD DEVIATION OF SALES | B39: =_xlfn.STDEV.S(Table1[Amount]) -> 2765.3967 | D39: Used STDEV.S to calculate the standard deviation of sales to understand the variability

Sheet One-dimensional Pivot Table
A1: TOTAL SALES BY PRODUCTS | E1: TOTAL SALES BY COUNTRY
A2: Row Labels | B2: Sum of Amount | E2: Row Labels | F2: Sum of Amount
A3: Apple | B3: 191257 | E3: Australia | F3: 131713
A4: Banana | B4: 340295 | E4: Canada | F4: 94745
A5: Beans | B5: 57281 | E5: France | F5: 141056
A6: Cabbage | B6: 142439 | E6: Germany | F6: 155168
A7: Carrots | B7: 136945 | E7: New Zealand | F7: 66782
A8: Mango | B8: 57079 | E8: United Kingdom | F8: 173137
A9: Orange | B9: 104438 | E9: United States | F9: 267133
A10: Grand Total | B10: 1029734 | E10: Grand Total | F10: 1029734
A13: TOTAL SALES BY CATEGORY | E13: AVERAGE SALES BY PRODUCT
A14: Row Labels | B14: Sum of Amount | E14: Row Labels | F14: Average of Amount
A15: Fruit | B15: 693069 | E15: Apple | F15: 4781.425
A16: Vegetables | B16: 336665 | E16: Banana | F16: 4792.8873
A17: Grand Total | B17: 1029734 | E17: Beans | F17: 4406.2308
E18: Cabbage | F18: 5275.5185
E19: Carrots | F19: 5072.037
E20: Mango | F20: 5189
E21: Orange | F21: 4351.5833
E22: Grand Total | F22: 4834.4319

Sheet Two-dimensional Pivot Table
A2: SALES BY COUNTRY AND PRODUCT
A3: Sum of Amount | B3: Column Labels
A4: Row Labels | B4: Australia | C4: Canada | D4: France | E4: Germany | F4: New Zealand | G4: United Kingdom | H4: United States | I4: Grand Total
A5: Apple | B5: 20634 | C5: 24867 | D5: 80193 | E5: 9082 | F5: 10332 | G5: 17534 | H5: 28615 | I5: 191257
A6: Banana | B6: 52721 | C6: 33775 | D6: 36094 | E6: 39686 | F6: 40050 | G6: 42908 | H6: 95061 | I6: 340295
A7: Beans | B7: 14433 | D7: 680 | E7: 29905 | G7: 5100 | H7: 7163 | I7: 57281
A8: Cabbage | B8: 17953 | C8: 12407 | D8: 5341 | E8: 37197 | F8: 4390 | G8: 38436 | H8: 26715 | I8: 142439
A9: Carrots | B9: 8106 | D9: 9104 | E9: 21636 | G9: 41815 | H9: 56284 | I9: 136945
A10: Mango | B10: 9186 | C10: 3767 | D10: 7388 | E10: 8775 | G10: 5600 | H10: 22363 | I10: 57079
A11: Orange | B11: 8680 | C11: 19929 | D11: 2256 | E11: 8887 | F11: 12010 | G11: 21744 | H11: 30932 | I11: 104438
A12: Grand Total | B12: 131713 | C12: 94745 | D12: 141056 | E12: 155168 | F12: 66782 | G12: 173137 | H12: 267133 | I12: 1029734
A15: SALES BY CATEGORY AND COUNTRY
A16: Sum of Amount | B16: Column Labels
A17: Row Labels | B17: Australia | C17: Canada | D17: France | E17: Germany | F17: New Zealand | G17: United Kingdom | H17: United States | I17: Grand Total
A18: Fruit | B18: 91221 | C18: 82338 | D18: 125931 | E18: 66430 | F18: 62392 | G18: 87786 | H18: 176971 | I18: 693069
A19: Vegetables | B19: 40492 | C19: 12407 | D19: 15125 | E19: 88738 | F19: 4390 | G19: 85351 | H19: 90162 | I19: 336665
A20: Grand Total | B20: 131713 | C20: 94745 | D20: 141056 | E20: 155168 | F20: 66782 | G20: 173137 | H20: 267133 | I20: 1029734
A23: SALES BY PRODUCTS AND MONTH
A24: Sum of Amount | B24: Column Labels
A25: Row Labels | B25: Jan | C25: Feb | D25: Mar | E25: Apr | F25: May | G25: Jun | H25: Jul | I25: Aug | J25: Sep | K25: Oct | L25: Nov | M25: Dec | N25: Grand Total
A26: Apple | B26: 16794 | C26: 19715 | D26: 25702 | E26: 14586 | F26: 22557 | G26: 6126 | H26: 2034 | I26: 22611 | J26: 8489 | K26: 15331 | L26: 11978 | M26: 25334 | N26: 191257
A27: Banana | B27: 29728 | C27: 9228 | D27: 26224 | E27: 16001 | F27: 69521 | G27: 15208 | H27: 31336 | I27: 9980 | J27: 51835 | K27: 22320 | L27: 29530 | M27: 29384 | N27: 340295
A28: Beans | B28: 2626 | C28: 15823 | D28: 6045 | F28: 8096 | H28: 8416 | I28: 5761 | K28: 5015 | M28: 5499 | N28: 57281
A29: Cabbage | B29: 30732 | C29: 1557 | D29: 5341 | E29: 9508 | F29: 17104 | G29: 25752 | H29: 13170 | I29: 20386 | J29: 18605 | L29: 284 | N29: 142439
A30: Carrots | B30: 6173 | C30: 5154 | D30: 21722 | E30: 8266 | F30: 28887 | H30: 5751 | I30: 9397 | J30: 7933 | K30: 9949 | L30: 7857 | M30: 25856 | N30: 136945
A31: Mango | C31: 9029 | D31: 3663 | F31: 33384 | H31: 5480 | J31: 5523 | N31: 57079
A32: Orange | B32: 3610 | C32: 2256 | D32: 15869 | E32: 1113 | F32: 23790 | G32: 4514 | H32: 14548 | I32: 859 | J32: 10048 | L32: 24091 | M32: 3740 | N32: 104438
A33: Grand Total | B33: 89663 | C33: 62762 | D33: 104566 | E33: 49474 | F33: 203339 | G33: 51600 | H33: 80735 | I33: 68994 | J33: 102433 | K33: 52615 | L33: 73740 | M33: 89813 | N33: 1029734
A37: PRODUCT TREND ANALYSIS
A38: Sum of Amount | B38: Column Labels
A39: Row Labels | B39: Fruit | C39: Vegetables | D39: Grand Total
A40: Jan | B40: 50132 | C40: 39531 | D40: 89663
A41: Feb | B41: 40228 | C41: 22534 | D41: 62762
A42: Mar | B42: 71458 | C42: 33108 | D42: 104566
A43: Apr | B43: 31700 | C43: 17774 | D43: 49474
A44: May | B44: 149252 | C44: 54087 | D44: 203339
A45: Jun | B45: 25848 | C45: 25752 | D45: 51600
A46: Jul | B46: 53398 | C46: 27337 | D46: 80735
A47: Aug | B47: 33450 | C47: 35544 | D47: 68994
A48: Sep | B48: 75895 | C48: 26538 | D48: 102433
...

Sheet DASHBOARD 
